<?xml version="1.0" encoding="utf-8"?>

<robot
  name="dronewithgripper_urdf">




  <link
    name="base_link">
    <inertial>
      <origin
        xyz="0 0 0"
        rpy="0 0 0" />
      <mass
        value="1.5" />
      <inertia
        ixx="0.0020044"
        ixy="0"
        ixz="-4.5897E-36"
        iyy="0.0020044"
        iyz="-1.8972E-36"
        izz="0.003927" />
    </inertial>
    <visual>
      <origin
        xyz="0 0 0"
        rpy="0 0 0" />
      <geometry>
        <mesh
          filename="base_link.STL" />
      </geometry>
      <material
        name="">
        <color
          rgba="0.5 0.5 0.5 1" />
      </material>
    </visual>
    <collision>
      <origin
        xyz="0 0 0"
        rpy="0 0 0" />
      <geometry>
        <mesh
          filename="base_link.STL" />
      </geometry>
    </collision>
  </link>
  
  <link
    name="front_left_prop">
    <inertial>
      <origin
        xyz="0 0 0.01"
        rpy="0 0 0" />
      <mass
        value="0.015708" />
      <inertia
        ixx="0.00010341"
        ixy="0"
        ixz="1.8367E-37"
        iyy="0.00010341"
        iyz="-1.5178E-37"
        izz="0.00019635" />
    </inertial>
    <visual>
      <origin
        xyz="0 0 0"
        rpy="0 0 0" />
      <geometry>
        <mesh
          filename="front_left_prop.STL" />
      </geometry>
      <material
        name="">
        <color
          rgba="1 0 0 1" />
      </material>
    </visual>
    <collision>
      <origin
        xyz="0 0 0"
        rpy="0 0 0" />
      <geometry>
        <mesh
          filename="front_left_prop.STL" />
      </geometry>
    </collision>
  </link>
  <joint
    name="base_link_to_front_left_prop"
    type="fixed">
    <origin
      xyz="0.1 0 0.1"
      rpy="1.5708 0 0" />
    <parent
      link="base_link" />
    <child
      link="front_left_prop" />
    <axis
      xyz="0 0 0" />
  </joint>
  <link
    name="front_right_prop">
    <inertial>
      <origin
        xyz="0 0 0.01"
        rpy="0 0 0" />
      <mass
        value="0.015708" />
      <inertia
        ixx="0.00010341"
        ixy="0"
        ixz="1.8367E-37"
        iyy="0.00010341"
        iyz="-1.5178E-37"
        izz="0.00019635" />
    </inertial>
    <visual>
      <origin
        xyz="0 0 0"
        rpy="0 0 0" />
      <geometry>
        <mesh
          filename="front_right_prop.STL" />
      </geometry>
      <material
        name="">
        <color
          rgba="0 0.5 0.1 1" />
      </material>
    </visual>
    <collision>
      <origin
        xyz="0 0 0"
        rpy="0 0 0" />
      <geometry>
        <mesh
          filename="front_right_prop.STL" />
      </geometry>
    </collision>
  </link>
  <joint
    name="base_link_to_front_right_prop"
    type="fixed">
    <origin
      xyz="0.1 0 -0.1"
      rpy="1.5708 0 0" />
    <parent
      link="base_link" />
    <child
      link="front_right_prop" />
    <axis
      xyz="0 0 0" />
  </joint>
  <link
    name="back_right_prop">
    <inertial>
      <origin
        xyz="0 0 0.01"
        rpy="0 0 0" />
      <mass
        value="0.015708" />
      <inertia
        ixx="0.00010341"
        ixy="0"
        ixz="1.8367E-37"
        iyy="0.00010341"
        iyz="-1.5178E-37"
        izz="0.00019635" />
    </inertial>
    <visual>
      <origin
        xyz="0 0 0"
        rpy="0 0 0" />
      <geometry>
        <mesh
          filename="back_right_prop.STL" />
      </geometry>
      <material
        name="">
        <color
          rgba="0 0 1 1" />
      </material>
    </visual>
    <collision>
      <origin
        xyz="0 0 0"
        rpy="0 0 0" />
      <geometry>
        <mesh
          filename="back_right_prop.STL" />
      </geometry>
    </collision>
  </link>
  <joint
    name="base_link_to_back_right_prop"
    type="fixed">
    <origin
      xyz="-0.1 0 -0.1"
      rpy="1.5708 0 0" />
    <parent
      link="base_link" />
    <child
      link="back_right_prop" />
    <axis
      xyz="0 0 0" />
  </joint>
  <link
    name="back_left_prop">
    <inertial>
      <origin
        xyz="0 0 0.01"
        rpy="0 0 0" />
      <mass
        value="0.015708" />
      <inertia
        ixx="0.00010341"
        ixy="0"
        ixz="1.8367E-37"
        iyy="0.00010341"
        iyz="-1.5178E-37"
        izz="0.00019635" />
    </inertial>
    <visual>
      <origin
        xyz="0 0 0"
        rpy="0 0 0" />
      <geometry>
        <mesh
          filename="back_left_prop.STL" />
      </geometry>
      <material
        name="">
        <color
          rgba="0 0 1 1" />
      </material>
    </visual>
    <collision>
      <origin
        xyz="0 0 0"
        rpy="0 0 0" />
      <geometry>
        <mesh
          filename="back_left_prop.STL" />
      </geometry>
    </collision>
  </link>
  <joint
    name="base_link_to_back_left_prop"
    type="fixed">
    <origin
      xyz="-0.1 0 0.1"
      rpy="1.5708 0 0" />
    <parent
      link="base_link" />
    <child
      link="back_left_prop" />
    <axis
      xyz="0 0 0" />
  </joint>
  <link
    name="gripper_base_link">
    <inertial>
      <origin
        xyz="-4.0731E-19 -3.2475E-19 -0.052057"
        rpy="0 0 0" />
      <mass
        value="0.5" />
      <inertia
        ixx="6.5574E-05"
        ixy="5.1451E-22"
        ixz="-2.1603E-21"
        iyy="6.4816E-05"
        iyz="-1.2511E-21"
        izz="3.7324E-05" />
    </inertial>
    <visual>
      <origin
        xyz="0 0 0"
        rpy="0 0 0" />
      <geometry>
        <mesh
          filename="gripper_base_link.STL" />
      </geometry>
      <material
        name="">
        <color
          rgba="0.5 0.5 0.5 1" />
      </material>
    </visual>
    <collision>
      <origin
        xyz="0 0 0"
        rpy="0 0 0" />
      <geometry>
        <mesh
          filename="gripper_base_link.STL" />
      </geometry>
    </collision>
  </link>
  <joint
    name="base_link_to_gripper_base_link"
    type="fixed">
    <origin
      xyz="0 -0.02 0"
      rpy="1.5708 -1.5708 0" />
    <parent
      link="base_link" />
    <child
      link="gripper_base_link" />
    <axis
      xyz="0 0 0" />
  </joint>
  <link
    name="left_gripper_link">
    <inertial>
      <origin
        xyz="-0.0091167 -0.020188 -0.005"
        rpy="0 0 0" />
      <mass
        value="0.015" />
      <inertia
        ixx="1.0169E-06"
        ixy="-2.5912E-07"
        ixz="2.2345E-23"
        iyy="2.2321E-07"
        iyz="-2.1251E-23"
        izz="1.1988E-06" />
    </inertial>
    <visual>
      <origin
        xyz="0 0 0"
        rpy="0 0 0" />
      <geometry>
        <mesh
          filename="left_gripper_link.STL" />
      </geometry>
      <material
        name="">
        <color
          rgba="1 0 0 1" />
      </material>
    </visual>
    <collision>
      <origin
        xyz="0 0 0"
        rpy="0 0 0" />
      <geometry>
        <mesh
          filename="left_gripper_link.STL" />
      </geometry>
    </collision>
  </link>
  <joint
    name="gripper_base_link_to_left_gripper_link"
    type="revolute">
    <origin
      xyz="0.009 0 -0.085"
      rpy="1.5708 0.71283 -1.5708" />
    <parent
      link="gripper_base_link" />
    <child
      link="left_gripper_link" />
    <axis
      xyz="0 0 -1" />
    <limit
      lower="0"
      upper="-0.9"
      effort="0"
      velocity="0" />
  </joint>
  <link
    name="right_gripper_link">
    <inertial>
      <origin
        xyz="-0.0091167 -0.020188 -0.005"
        rpy="0 0 0" />
      <mass
        value="0.015" />
      <inertia
        ixx="1.0169E-06"
        ixy="-2.5912E-07"
        ixz="7.6703E-23"
        iyy="2.2321E-07"
        iyz="2.104E-22"
        izz="1.1988E-06" />
    </inertial>
    <visual>
      <origin
        xyz="0 0 0"
        rpy="0 0 0" />
      <geometry>
        <mesh
          filename="right_gripper_link.STL" />
      </geometry>
      <material
        name="">
        <color
          rgba="0 1 0 1" />
      </material>
    </visual>
    <collision>
      <origin
        xyz="0 0 0"
        rpy="0 0 0" />
      <geometry>
        <mesh
          filename="right_gripper_link.STL" />
      </geometry>
    </collision>
  </link>
  <joint
    name="gripper_base_link_to_right_gripper_link"
    type="revolute">
    <origin
      xyz="-0.009 0 -0.085"
      rpy="1.5708 0.48112 1.5708" />
    <parent
      link="gripper_base_link" />
    <child
      link="right_gripper_link" />
    <axis
      xyz="0 0 1" />
    <limit
      lower="0"
      upper="0.6"
      effort="0"
      velocity="0" />
  </joint>
</robot>
