<?xml version="1.0"?>
<robot name="quadrotor">
  <link name="base_link">
    <visual>
      <origin xyz="0 0 0.0"/>
      <geometry>
        <cylinder radius="0.1" length="0.025"/>
      </geometry>
      <material name="Grey">
        <color rgba="0.5 0.5 0.5 1.0"/>
      </material>
    </visual>
    <collision>
      <origin xyz="0 0 0"/>
      <geometry>
        <cylinder radius="0.2" length="0.04"/>
      </geometry>
    </collision>
    <inertial>
      <mass value="1.9"/>
      <inertia ixx="0.05" ixy="0.0" ixz="0.0" iyy="0.05" iyz="0.0" izz="0.05"/>
    </inertial>
  </link>
  <link name="front_left_prop">
    <visual>
      <origin xyz="0 0 0"/>
      <geometry>
        <cylinder radius="0.05" length="0.02"/>
      </geometry>
      <material name="Red">
        <color rgba="1 0 0 1.0"/>
      </material>
    </visual>
    <inertial>
      <mass value="0.01"/>
      <inertia ixx="0.000001" ixy="0.0" ixz="0.0" iyy="0.000001" iyz="0.0" izz="0.000001"/>
    </inertial>
  </link>
  <link name="front_right_prop">
    <visual>
      <origin xyz="0 0 0"/>
      <geometry>
        <cylinder radius="0.05" length="0.02"/>
      </geometry>
      <material name="Red">
        <color rgba="0 0.50 0.1 1.0"/>
      </material>
    </visual>
    <inertial>
      <mass value="0.01"/>
      <inertia ixx="0.000001" ixy="0.0" ixz="0.0" iyy="0.000001" iyz="0.0" izz="0.000001"/>
    </inertial>
  </link>
  <link name="back_left_prop">
    <visual>
      <origin xyz="0 0 0"/>
      <geometry>
        <cylinder radius="0.05" length="0.02"/>
      </geometry>
      <material name="Blue">
        <color rgba="0 0 1 1.0"/>
      </material>
    </visual>
    <inertial>
      <mass value="0.01"/>
      <inertia ixx="0.000001" ixy="0.0" ixz="0.0" iyy="0.000001" iyz="0.0" izz="0.000001"/>
    </inertial>
  </link>
  <link name="back_right_prop">
    <visual>
      <origin xyz="0 0 0"/>
      <geometry>
        <cylinder radius="0.05" length="0.02"/>
      </geometry>
      <material name="Blue">
        <color rgba="0 0 1 1.0"/>
      </material>
    </visual>
    <inertial>
      <mass value="0.01"/>
      <inertia ixx="0.000001" ixy="0.0" ixz="0.0" iyy="0.000001" iyz="0.0" izz="0.000001"/>
    </inertial>
  </link>
  <joint name="base_link_to_front_left_prop" type="fixed" dont_collapse="true">    
    <parent link="base_link"/>    
    <child link="front_left_prop"/>    
    <origin xyz="0.100 0.100 0"/>  
  </joint>
  <joint name="base_link_to_front_right_prop" type="fixed" dont_collapse="true">    
    <parent link="base_link"/>    
    <child link="front_right_prop"/>    
    <origin xyz="0.100 -0.100 0"/>
  </joint>
  <joint name="base_link_to_back_right_prop" type="fixed" dont_collapse="true">    
    <parent link="base_link"/>    
    <child link="back_right_prop"/>    
    <origin xyz="-0.100 -0.100 0"/> 
  </joint>
  <joint name="base_link_to_back_left_prop" type="fixed" dont_collapse="true">    
    <parent link="base_link"/>    
    <child link="back_left_prop"/>    
    <origin xyz="-0.100 0.100 0"/> 
  </joint>

  <!-- Add the gripper -->
  <link name="gripper_base">
    <visual>
      <origin xyz="0 0 -0.2"/>
      <geometry>
        <box size="0.1 0.1 0.02"/>
      </geometry>
      <material name="black"/>
    </visual>
    <collision>
      <origin xyz="0 0 -0.2"/>
      <geometry>
        <box size="0.1 0.1 0.02"/>
      </geometry>
    </collision>
    <inertial
      <mass value="0.1"/>
      <inertia ixx="0.0001" ixy="0.0" ixz="0.0" iyy="0.0001" iyz="0.0" izz="0.0001"/>
    </inertial>
  </link>
  <joint name="base_link_to_gripper_base" type="fixed">
    <parent link="base_link"/>
    <child link="gripper_base"/>
    <origin xyz="0 0 -0.2" rpy="0 0 0"/>
  </joint>

  <link name="finger_left">
    <visual>
      <origin xyz="0.05 0 -0.02" rpy="0 0 0"/>
      <geometry>
        <box size="0.02 0.1 0.02"/>
      </geometry>
      <material name="gray"/>
    </visual>
    <collision>
      <origin xyz="0.05 0 -0.02" rpy="0 0 0"/>
      <geometry>
        <box size="0.02 0.1 0.02"/>
      </geometry>
    </collision>
    <inertial>
      <mass value="0.01"/>
      <inertia ixx="0.00001" ixy="0.0" ixz="0.0" iyy="0.00001" iyz="0.0" izz="0.00001"/>
    </inertial>
  </link>
  <joint name="gripper_base_to_finger_left" type="revolute">
    <parent link="gripper_base"/>
    <child link="finger_left"/>
    <origin xyz="0.05 0 -0.02" rpy="0 0 0"/>
    <axis xyz="0 1 0"/>
    <limit lower="-0.05" upper="0.05" effort="0.5" velocity="1.0"/>
  </joint>

  <link name="finger_right">
    <visual>
      <origin xyz="-0.05 0 -0.02" rpy="0 0 0"/>
      <geometry>
        <box size="0.02 0.1 0.02"/>
      </geometry>
      <material name="gray"/>
    </visual>
    <collision>
      <origin xyz="-0.05 0 -0.02" rpy="0 0 0"/>
      <geometry>
        <box size="0.02 0.1 0.02"/>
      </geometry>
    </collision>
    <inertial>
      <mass value="0.01"/>
      <inertia ixx="0.00001" ixy="0.0" ixz="0.0" iyy="0.00001" iyz="0.0" izz="0.00001"/>
    </inertial>
  </link>
  <joint name="gripper_base_to_finger_right" type="revolute">
    <parent link="gripper_base"/>
    <child link="finger_right"/>
    <origin xyz="-0.05 0 -0.02" rpy="0 0 0"/>
    <axis xyz="0 1 0"/>
    <limit lower="-0.05" upper="0.05" effort="0.5" velocity="1.0"/>
  </joint>
</robot>
